Workbook

Sheet README
B2: Nordic Orphan Drug Market Access Analysis
B3: Sweden, Denmark, Norway | 51 drugs x 3 countries = 174 evaluation records | Finland excluded (see section 1b) | Rebuilt 2026-06-22
B5: 1. Data sources & provenance
B6: PRIMARY SOURCE (high confidence): "Rare Diseases Database.xlsx" - a structured HTA tracking spreadsheet covering 51 orphan/rare-disease drugs evaluated by Sweden (TLV/NT-radet), Denmark (Medicinradet/Amgros), and Norway (DMP/Nye Metoder/Beslutningsforum). All 174 records in the Master Data sheet originate here unless flagged otherwise in the Data_Source column. Three drugs (Strensiq, Myalepta, Luxturna) were added 2026-06-22 from primary TLV/DMP/Medicinradet/Beslutningsforum documents supplied by the user and independently web-verified (see section 1c).
B7: SUPPLEMENTARY SOURCE (lower confidence, Finland only): "Skysona_merged.pdf" - a 139-page AI-assisted research compilation. This source was used only for Finland data, which is now excluded from this analysis entirely (section 1b) - so this supplementary source no longer feeds any row in Master Data. It is retained in the source folder for provenance/audit purposes only.
B8: All judgment-based classifications below should be treated as best-available analytical estimates pending independent verification against primary TLV / Medicinradet / Nye Metoder publications - NOT as verified primary-source facts.
B10: 1b. Finland exclusion - rationale
B11: Finland is deliberately excluded from this analysis, not merely filtered out as a zero-result row. The reason is a data-completeness/reliability asymmetry, not a finding about Finnish HTA practice: unlike Sweden (TLV), Denmark (Medicinradet/Amgros) and Norway (DMP/Beslutningsforum), no comparable set of primary-source Finnish HTA documents (Fimea assessment reports, PALKO/HILA decisions) was ever assembled for this project. The only Finland data available came from an AI-assisted research compilation (Skysona_merged.pdf), which is demonstrably a secondary/derived source (it contains a self-referential note to a prior AI tool's "follow-up suggestion") rather than a primary HTA publication.
B12: Carrying Finland forward on that basis would silently mix one fundamentally lower-confidence evidence tier into every cross-country comparison in this workbook (rates, trends, restriction levels, Fisher's-exact tests), without a way to flag the difference in a live pivot/COUNTIFS table. The scientifically defensible choice is to exclude Finland entirely until primary Fimea/PALKO/HILA source documents are obtained, rather than report findings that imply a confidence level the underlying Finland data does not support. This mirrors standard HTA evidence-synthesis practice of excluding, rather than downweighting in place, sources that fail a minimum evidentiary-quality bar.
B13: If primary Finnish HTA documents become available, Finland can be reintroduced by re-adding country block data to Rare Diseases Database.xlsx and removing it from the EXCLUDED_COUNTRIES set in the build pipeline (build_master.py) - no other structural change is required.
B15: 1c. Web-verification of newly added drugs (2026-06-22)
B16: Strensiq, Myalepta and Luxturna were added from primary-source PDFs (TLV beslut, DMP metodevurdering/Beslutningsforum sakspapirer, Medicinradet anbefaling) supplied directly by the user. Each drug's key facts (decision outcome, date, case/diary number) were independently checked against public web sources on 2026-06-22; no contradictions were found. Two facts remain genuinely unconfirmed in any source checked (document or web) and are reported as such rather than guessed: (1) the outcome of Myalepta's January 2023 Beslutningsforum vote restricted to the GL (generalised lipodystrophy) subgroup in Norway; (2) any Strensiq decision in Norway after the 27 Sept 2021 "not recommended / under renegotiation" status. Both are recorded with Decision Status "Not recommended / Under renegotiation" reflecting the last confirmed state, not an assumption of a later outcome.
... B46: Every column in Master Data is evaluable (non-null/non-trivial) for at least one country per drug where an HTA process occurred; "Not Evaluated" rows correctly carry blank decision-specific fields (Decision_Date, Comparator, ICER, etc.) rather than placeholder text, by design (see Access_Outcome). The Evidence_Type column is the one parameter with a structural coverage gap: most source records do not describe trial design explicitly, so most rows are coded "Not specified/unclear" - this is a genuine source-data limitation, not a classifier defect, and is flagged here rather than silently presented as a usable cross-tab dimension. The 3-tier Severity_Tier scheme is a simplification that fits most drugs cleanly but is a coarse fit for a few atypical cases (e.g. Luxturna, a one-time gene therapy for a non-immediately-fatal but vision-threatening pediatric condition, sits awkwardly between "Severe" and "Serious"); it is retained for cross-drug comparability but should not be read as a precise clinical grading.

Sheet Master Data
A1: Drug | B1: INN | C1: Disease | D1: Applicant | E1: Parent_Company | F1: Technology | G1: Therapeutic_Area | H1: Severity_Tier | I1: Country | J1: Decision_Type | K1: Evaluation_Raw | L1: Decision_Status_Raw | M1: Access_Outcome | N1: Restriction_Level | O1: Reason_Category | P1: Decision_Year | Q1: Decision_Date_Raw | R1: Comparator_Category | S1: Comparator_Raw | T1: Evidence_Type | U1: Reason_Text | V1: ICER_Raw | W1: Main_Uncertainty | X1: Conditions | Y1: Notes | Z1: Comments | AA1: Data_Source | AB1: Row_Ref | AC1: Is_Positive | AD1: Is_Assessed | AE1: ICER_Min_SEK_per_QALY (Sweden only, curated) | AF1: ICER_Max_SEK_per_QALY (Sweden only, curated) | AG1: ICER_Basis_Note (Sweden only) | AH1: Technology_Group | AI1: Drug_Any_Positive (helper) | AJ1: Drug_First_Positive_Year (helper)
A2: Zolgensma | B2: Onasemnogene abeparvovec | C2: 5q Spinal muscular atrophy (SMA) | D2: Novartis Gene Therapies | E2: Novartis | F2: Gene therapy (in vivo AAV) | G2: Neuromuscular | H2: Ultra-severe (immediately life-threatening) | I2: Sweden | J2: Full / standard HTA | K2: Health Economic Assessment with Scenario Analysis | L2: Not Recommended (Uncertainty) | M2: Negative | N2: Not Applicable | O2: Clinical evidence uncertainty | P2: 2021 | Q2: 2021-02-24 00:00:00 | R2: Active comparator drug(s) | S2: Spinraza + BSC or BSC | T2: Not specified / unclear | U2: Clinical evidence uncertainty | V2: SEK 850,000 - 3.2 million/QALY vs Spinraza + BSC or SEK 2.9–5.7 million/QALY vs BSC alone | W2: Very high uncertainty about long-term effects, how long the treatment effect lasts and uncertainty due to model based on muldtiple linked data sources | X2: Patients with 5q SMA with biallelic SMN1 mutation and either a clinical diagnosis of SMA type 1, or up to 3 copies of the SMN2 gene. TLV's economic scenarios mainly apply to symptomatic SMA type 1. No conclusions or results were presented for presymptomaic patients or symptomatic SMA type 2/3 due to uncertaintly in relative effectiveness. | Y2: Health Economic Assessment completed by TLV - no base-case scenario established for some patient groups due to uncertainty | Z2: TLV presents multiple scenario analyses wather than one base case for symptomatic SMA type 1. No results are presented for presymptomatic patients or symptomatic SMA type 2/3 because TLV considers relative effectiveness vs Spinraza too uncertain. Patient follow-up is considered important. | AA2: Primary xlsx database | AB2: 4 | AC2: =IF(OR($M2="Positive",$M2="Restricted Positive"),1,0) -> 0 | AD2: =IF($M2="Not Evaluated",0,1) -> 1 | AE2: 850000 | AF2: 5700000 | AG2: range (vs Spinraza+BSC: 0.85-3.2M; vs BSC alone: 2.9-5.7M) | AH2: Gene therapy | AI2: =IF(COUNTIFS($A$2:$A$175,$A2,$C$2:$C$175,$C2,$AC$2:$AC$175,1)>0,1,0) -> 1 | AJ2: =IFERROR(_xludf.MINIFS($P$2:$P$175,$A$2:$A$175,$A2,$C$2:$C$175,$C2,$AC$2:$AC$175,1),"")
A3: Zolgensma | B3: Onasemnogene abeparvovec | C3: 5q Spinal muscular atrophy (SMA) | D3: Novartis Gene Therapies | E3: Novartis | F3: Gene therapy (in vivo AAV) | G3: Neuromuscular | H3: Ultra-severe (immediately life-threatening) | I3: Denmark | J3: Full / standard HTA | K3: Clinical Value assessment + health economic assessment - Cost Minimization Approach | L3: Recommended | M3: Positive | N3: Broad | O3: N/A | P3: 2021 | Q3: Original recommendation: 26 May 2021; follow-up maintained: 23 Aug 2023; replaced by SMA guidance: 31 Aug 2023 | R3: Active comparator drug(s) | S3: Nusinersen/Spinraza, given continuously every 4 months | T3: Not specified / unclear | U3: Clinical evidence uncertainty + Price / cost-effectiveness | V3: No ICER reported. Medicinrådet used cost-minimisation because Zolgensma and nusinersen were considered clinically equivalent. Costs per patient were expected to equalise after 8–15 years, with substantial uncertainty; using AIP, equalisation was around 9 years | W3: Long-term effect and long-term safety of one-time Zolgensma treatment. Uncertainty about how long nusinersen treatment would continue. Uncertainty around when costs equalize. | X3: Infants with SMA type 1 treated before 6 months old and not in permanent ventilation >16h/day, also presymptomatic infants born with SMA. Switching from comparator may be considered only in special cases if the child weights <13.5kg, is not severely muscle-weak and can breathe independently. | Y3: Medicinrådet considered Zolgensma clinically equivalent to nusinersen overall. The applicant’s full health economic model was only used to a limited extent because assumptions about effect, disease progression and mortality were not sufficiently supported by data. Medicinrådet instead used a simplified cost-minimisation approach | Z3: Zolgensma was not recommended in combination with nusinersen. The recommendation did not mean Zolgensma should automatically be first choice for all patients, switching from well-functioning nusinersen generally requires a specific clinical reason | AA3: Primary xlsx database | AB3: 4 | AC3: =IF(OR($M3="Positive",$M3="Restricted Positive"),1,0) -> 1 | AD3: =IF($M3="Not Evaluated",0,1) -> 1 | AH3: Gene therapy | AI3: =IF(COUNTIFS($A$2:$A$175,$A3,$C$2:$C$175,$C3,$AC$2:$AC$175,1)>0,1,0) -> 1 | AJ3: =IFERROR(_xludf.MINIFS($P$2:$P$175,$A$2:$A$175,$A3,$C$2:$C$175,$C3,$AC$2:$AC$175,1),"")
A4: Zolgensma | B4: Onasemnogene abeparvovec | C4: 5q Spinal muscular atrophy (SMA) | D4: Novartis Gene Therapies | E4: Novartis | F4: Gene therapy (in vivo AAV) | G4: Neuromuscular | H4: Ultra-severe (immediately life-threatening) | I4: Norway | J4: Rapid / simplified HTA | K4: Simplified method assessment: effect, safety and cost assessment + managed-access negotiation | L4: Introduced by Beslutningsforum for treatment of SMA - currently under reassessment because updated follow-up documentation was not submitted on time | M4: Positive | N4: Broad | O4: N/A | P4: 2021 | Q4: Final introduction: 25 Oct 2021; reassessment request: 19 Jan 2026; deadline extended to 15 Jun 2026 on 27 Apr 2026 | R4: Active comparator drug(s) | S4: Nusinersen/Spinraza | T4: Real-world / registry / natural history | U4: Clinical evidence uncertainty + Price / cost-effectiveness | V4: No standard ICER/cost per QALY reported. Cost comparison only; Zolgensma had a very high one-time cost, around NOK 27 million before possible discounts | W4: Sparse evidence base, short follow-up, major uncertainty about long-term effect, uncertainty about comparison with Spinraza and long-term costs | X4: Infants <6 months with manifest 5q SMA type 1 and biallelic SMN1 mutation, without clear symptoms at birth/type 0 and without ventilation support >16 h/day, presymptomatic infants <6 months with biallelic SMN1 mutation and 2 or 3 SMN2 copies, elected 6–18 month children <13.5 kg may switch from Spinraza in special cases if not severely weak and able to breathe independently, <6 month patients already started on Spinraza before Zolgensma availability could convert | Y4: Simplified HTA assessing effect, safety and costs. Zolgensma was compared with Spinraza. Final introduction was possible after negotiations and a result-based price agreement | Z4: First result-based agreement for a medicine in Norway. Treatment centralised at Oslo University Hospital, registry follow-up required, no combination with Spinraza or other disease-modifying treatment. In 2026, caution advised for new patients pending reassessment | AA4: Primary xlsx database | AB4: 4 | AC4: =IF(OR($M4="Positive",$M4="Restricted Positive"),1,0) -> 1 | AD4: =IF($M4="Not Evaluated",0,1) -> 1 | AH4: Gene therapy | AI4: =IF(COUNTIFS($A$2:$A$175,$A4,$C$2:$C$175,$C4,$AC$2:$AC$175,1)>0,1,0) -> 1 | AJ4: =IFERROR(_xludf.MINIFS($P$2:$P$175,$A$2:$A$175,$A4,$C$2:$C$175,$C4,$AC$2:$AC$175,1),"")
A5: Evrysdi | B5: Risdiplam | C5: 5q Spinal muscular atrophy (SMA) | D5: Roche AB | E5: Roche | F5: Small molecule | G5: Neuromuscular | H5: Ultra-severe (immediately life-threatening) | I5: Sweden | J5: Managed introduction / price negotiation | K5: Reimbursement / Subvention Assessment with Cost-Utility Analysis, later restricted subvention after side agreement | L5: 2021: Rejected. 2025: Reimbursed with restriction | M5: Restricted Positive | N5: Restricted | O5: Price/Cost-effectiveness | P5: 2021 | Q5: 21/10/2021; 01/02/2025; tablet added 26/08/2025 | R5: Active comparator drug(s) | S5: BSC / no addition to BSC; tablet compared with Evrysdi oral solution | T5: Not specified / unclear | U5: Clinical evidence uncertainty + Price / cost-effectiveness | V5: 2021: SEK 2.3–3.1M/QALY for SMA type 1; SEK 7.9M/QALY for SMA type 2/3. 2025: SEK 4.9M/QALY for SMA type 1; approx. SEK 800k/QALY for SMA type 2/3 after side agreement | W5: Long-term effect, survival, QoL, model uncertainty, transferability to Swedish population, personal assistance costs | X5: 5q SMA type 1, type 2 or type 3. Tablet: patients >2 years and ≥20 kg under same restriction | Y5: Initial rejection due to costs not being reasonable vs benefit, later approval enabled by side agreement between Roche and regions | Z5: Important reversal case: price agreement changed outcome. SMA type 1 included via need-solidarity principle, tablet decision was a formulation extension | AA5: Primary xlsx database | AB5: 5 | AC5: =IF(OR($M5="Positive",$M5="Restricted Positive"),1,0) -> 1 | AD5: =IF($M5="Not Evaluated",0,1) -> 1 | AE5: 800000 | AF5: 7900000 | AG5: range across 2021 and 2025 reassessments, by SMA subtype | AH5: Small molecule | AI5: =IF(COUNTIFS($A$2:$A$175,$A5,$C$2:$C$175,$C5,$AC$2:$AC$175,1)>0,1,0) -> 1 | AJ5: =IFERROR(_xludf.MINIFS($P$2:$P$175,$A$2:$A$175,$A5,$C$2:$C$175,$C5,$AC$2:$AC$175,1),"")
A6: Evrysdi | B6: Risdiplam | C6: 5q Spinal muscular atrophy (SMA) | D6: Roche AB | E6: Roche | F6: Small molecule | G6: Neuromuscular | H6: Ultra-severe (immediately life-threatening) | I6: Denmark | J6: Full / standard HTA | K6: Clinical Value Assessment + health economic assessment - later integrated into SMA treatment guidance and drug recommendation | L6: 2021: Recommended for selected SMA patients. 2024: Recommendation expanded after reassessment based on new price and new data. 2026: Evrysdi placed as first-choice option in current SMA drug recommendation | M6: Positive | N6: Broad | O6: N/A | P6: 2021 | Q6: Original recommendation: 27/10/2021. Reassessment/expanded recommendation: 28/08/2024. Current guidance: 29/04/2026 | R6: Active comparator drug(s) | S6: Nusinersen for SMA type 1 and selected SMA type 2/3 groups; BSC/placebo/no medical treatment for groups where nusinersen was not standard care | T6: Not specified / unclear | U6: Clinical evidence uncertainty + Price / cost-effectiveness | V6: No ICER reported. Medicinrådet used incremental cost and budget impact analyses. In 2021, risdiplam was less costly than nusinersen in recommended groups; list-price analyses showed high incremental costs vs BSC in older/non-recommended groups | W6: Sparse data for SMA type 1, short follow-up, uncertain effect in older children/adults in original assessment, uncertainty around long-term survival, treatment duration and accumulated medicine costs | X6: 2021: SMA type 1 patients not in permanent ventilation >16 h/day; SMA type 2/3 patients under 6 years at treatment start. Later expanded to patients meeting fixed start/stop criteria. Current guidance includes Evrysdi as first choice for SMA type 1/presymptomatic infants, SMA type 2/3 children, young people and adults, including adults >25 years meeting criteria | Y6: Risdiplam was initially recommended because it was considered as good as nusinersen for relevant younger patients and less costly. Older SMA type 2/3 patients were not included in 2021 due to insufficient evidence. Later evidence and pricing supported broader use | Z6: Important expansion case: access broadened over time through new data, new price and integration into SMA pathway guidance. Evrysdi is oral and taken at home, unlike nusinersen. Combination therapy with other SMA medicines is not recommended | AA6: Primary xlsx database | AB6: 5 | AC6: =IF(OR($M6="Positive",$M6="Restricted Positive"),1,0) -> 1 | AD6: =IF($M6="Not Evaluated",0,1) -> 1 | AH6: Small molecule | AI6: =IF(COUNTIFS($A$2:$A$175,$A6,$C$2:$C$175,$C6,$AC$2:$AC$175,1)>0,1,0) -> 1 | AJ6: =IFERROR(_xludf.MINIFS($P$2:$P$175,$A$2:$A$175,$A6,$C$2:$C$175,$C6,$AC$2:$AC$175,1),"")
A7: Evrysdi | B7: Risdiplam | C7: 5q Spinal muscular atrophy (SMA) | D7: Roche AB | E7: Roche | F7: Small molecule | G7: Neuromuscular | H7: Ultra-severe (immediately life-threatening) | I7: Norway | J7: Rapid / simplified HTA | K7: Multiple Evaluations: Simplified HTA (ID2021_088), Full HTA (ID2020_104), indication extensions and pricing reviews (ID2023_089, ID2025_010) | L7: Recommended (Introduced through stepwise indication expansions) | M7: Positive | N7: Broad | O7: N/A | P7: 2022 | Q7: Initial reimbursement: 17/01/2022. Expanded: 22/01/2024. Tablet formulation: 2025 | R7: Active comparator drug(s) | S7: Nusinersen (Spinraza) for children already eligible for treatment; supportive care/no disease-modifying treatment for adults and SMA type 3b populations | T7: Not specified / unclear | U7: Clinical evidence uncertainty + Comparator/positioning issue + Price / cost-effectiveness | V7: Full HTA (ID2020_104) estimated approximately NOK 12 million per QALY gained versus supportive care. No ICER reported in simplified assessments. | W7: Limited long-term evidence, small patient populations, uncertainty regarding long-term effectiveness and durability of treatment effect, particularly in adults | X7: Initially approved for children ≥2 months with SMA type 1, 2 or 3a. Later expanded to infants <2 months and subsequently to broader adult populations. National start/stop criteria apply. | Y7: Norway used different evaluation pathways depending on the patient population. Children already eligible for Spinraza underwent a simplified assessment, while adults and type 3b patients underwent a full HTA. | Z7: Market access was achieved through gradual indication expansion. Adult access required additional assessment and price negotiations. Tablet formulation was approved through a suitability assessment and pricing review rather than a new HTA. | AA7: Primary xlsx database | AB7: 5 | AC7: =IF(OR($M7="Positive",$M7="Restricted Positive"),1,0) -> 1 | AD7: =IF($M7="Not Evaluated",0,1) -> 1 | AH7: Small molecule | AI7: =IF(COUNTIFS($A$2:$A$175,$A7,$C$2:$C$175,$C7,$AC$2:$AC$175,1)>0,1,0) -> 1 | AJ7: =IFERROR(_xludf.MINIFS($P$2:$P$175,$A$2:$A$175,$A7,$C$2:$C$175,$C7,$AC$2:$AC$175,1),"")
A8: Spinraza | B8: Nusinersen | C8: 5q Spinal muscular atrophy (SMA) | D8: Biogen Sweden AB | E8: Biogen | F8: RNA-targeted (antisense oligonucleotide) | G8: Neuromuscular | H8: Ultra-severe (immediately life-threatening) | I8: Sweden | J8: Full / standard HTA | K8: Health Economic Assessment with Scenario Analysis | L8: Recomended (Reassessed 2023) | M8: Positive | N8: Broad | O8: N/A | P8: 2017 | Q8: 10/11/2017; 18/10/2023 | R8: Best supportive care / no active treatment | S8: BSC | T8: Real-world / registry / natural history | U8: Clinical evidence uncertainty | V8: 2017: SMA I SEK 5.7–7.7M/QALY; SMA II SEK 7.3–12.8M/QALY. 2023: Pediatric SMA I SEK 4.1–7.3M/QALY; Pediatric SMA II SEK 4.8–7.7M/QALY | W8: Long-term survival, durability of treatment effect, quality-of-life estimates, disease progression modelling and limited evidence for adult SMA populations | X8: Patients with 5q SMA type I, II and III. Reassessment included pediatric SMA type I/II and adult SMA type II/III populations | Y8: Initial TLV assessment followed by major reassessment using long-term evidence and real-world data | Z8: Spinraza became the reference therapy against which both Zolgensma and Evrysdi were later assessed in Sweden. Reassessment demonstrated improved evidence base but uncertainty remained for adult SMA populations. | AA8: Primary xlsx database | AB8: 6 | AC8: =IF(OR($M8="Positive",$M8="Restricted Positive"),1,0) -> 1 | AD8: =IF($M8="Not Evaluated",0,1) -> 1 | AE8: 4100000 | AF8: 12800000 | AG8: range across 2017 and 2023 reassessments, by SMA subtype | AH8: RNA-targeted | AI8: =IF(COUNTIFS($A$2:$A$175,$A8,$C$2:$C$175,$C8,$AC$2:$AC$175,1)>0,1,0) -> 1 | AJ8: =IFERROR(_xludf.MINIFS($P$2:$P$175,$A$2:$A$175,$A8,$C$2:$C$175,$C8,$AC$2:$AC$175,1),"")
A9: Spinraza | B9: Nusinersen | C9: 5q Spinal muscular atrophy (SMA) | D9: Biogen Sweden AB | E9: Biogen | F9: RNA-targeted (antisense oligonucleotide) | G9: Neuromuscular | H9: Ultra-severe (immediately life-threatening) | I9: Denmark | J9: Managed introduction / price negotiation | K9: Repeated HTA and reimbursement reassessments (2017, 2018, 2020) followed by national treatment guideline priorisation (2023) | L9: Restricted Recommendation / Recommended only for defined SMA subgroups; Not recommended for general SMA population | M9: Restricted Positive | N9: Restricted | O9: Clinical evidence uncertainty | P9: 2017 | Q9: 12/10/2017; 30/01/2018; 30/05/2018; 27/10/2020; 31/08/2023 | R9: Active comparator drug(s) | S9: BSC (initial assessments) + later compared directly with risdiplamn and onasemnogene in treatment guideline reviews | T9: Not specified / unclear | U9: Administrative/procedural + Clinical evidence uncertainty + Comparator/positioning issue + Price / cost-effectiveness | V9: No ICER publicly reported in Medicinrådet recommendations; decisions based on clinical value relative to negotiated price | W9: Limited long-term efficacy data, particularly for SMA type 2 and type 3; uncertainty regarding treatment effect in older children, adults and patients with longer disease duration; lack of evidence for SMA type 3 and adults | X9: Recommended for presymptomatic infants with 2–4 SMN2 copies, SMA type 1 and selected SMA type 2 patients meeting strict clinical criteria (including early treatment initiation and limited disease duration). Not recommended for SMA type 3 or general SMA populations. | Y9: Multiple reassessments due to new evidence and price negotiations. Medicinrådet repeatedly concluded that the price remained disproportionately high relative to documented benefit but accepted restricted use based on disease severity and demonstrated benefit in selected populations. | Z9: Illustrates Denmark’s highly restrictive access approach for rare disease therapies. Access expanded gradually as evidence accumulated, but recommendations remained limited to subgroups with strongest evidence. In 2023 Spinraza became a second-line option behind Evrysdi in most paediatric populations. | AA9: Primary xlsx database | AB9: 6 | AC9: =IF(OR($M9="Positive",$M9="Restricted Positive"),1,0) -> 1 | AD9: =IF($M9="Not Evaluated",0,1) -> 1 | AH9: RNA-targeted | AI9: =IF(COUNTIFS($A$2:$A$175,$A9,$C$2:$C$175,$C9,$AC$2:$AC$175,1)>0,1,0) -> 1 | AJ9: =IFERROR(_xludf.MINIFS($P$2:$P$175,$A$2:$A$175,$A9,$C$2:$C$175,$C9,$AC$2:$AC$175,1),"")
A10: Spinraza | B10: Nusinersen | C10: 5q Spinal muscular atrophy (SMA) | D10: Biogen Sweden AB | E10: Biogen | F10: RNA-targeted (antisense oligonucleotide) | G10: Neuromuscular | H10: Ultra-severe (immediately life-threatening) | I10: Norway | J10: Rapid / simplified HTA | K10: Rapid HTA (2017), multiple reassessments (2018, 2023) and price negotiations | L10: Recommended with restrictions (following initial non-recommendation) | M10: Restricted Positive | N10: Restricted | O10: N/A | P10: 2017 | Q10: 23/10/2017; 08/12/2017; 12/02/2018; 22/10/2018; 11/04/2023 | R10: Best supportive care / no active treatment | S10: BSC / no disease modifying treatment | T10: Real-world / registry / natural history | U10: Clinical evidence uncertainty + Price / cost-effectiveness | V10: Initial HTA estimated ICERs ranging from approximately NOK 16–40 million per QALY in the Norwegian Medicines Agency base-case scenarios, depending on SMA subtype. | W10: Long-term effectiveness, durability of treatment effect, limited trial data, uncertainty in health-economic model, effectiveness in older patients and later disease stages | X10: Restricted to defined paediatric SMA populations under strict start/stop criteria, national expert review, registry participation and regular reassessment. Expanded in 2023 to include SMA type 3b children. | Y10: Initially rejected because price was considered unacceptable and evidence uncertain. Following substantial price negotiations, Spinraza was introduced under one of the most restrictive managed-access schemes in Norway. | Z10: Illustrates Norway’s use of managed access, price negotiation, registry-based monitoring and start/stop criteria to manage uncertainty for an ultra-rare disease therapy. | AA10: Primary xlsx database | AB10: 6 | AC10: =IF(OR($M10="Positive",$M10="Restricted Positive"),1,0) -> 1 | AD10: =IF($M10="Not Evaluated",0,1) -> 1 | AH10: RNA-targeted | AI10: =IF(COUNTIFS($A$2:$A$175,$A10,$C$2:$C$175,$C10,$AC$2:$AC$175,1)>0,1,0) -> 1 | AJ10: =IFERROR(_xludf.MINIFS($P$2:$P$175,$A$2:$A$175,$A10,$C$2:$C$175,$C10,$AC$2:$AC$175,1),"")
A11: Libmeldy | B11: Atidarsagene autotemcel | C11: Metachromatic leukodystrophy | D11: Orchard Therapeutics (Kyowa Kirin) | E11: Kyowa Kirin | F11: Gene therapy (ex vivo lentiviral) | G11: Neurology (metabolic) | H11: Ultra-severe (immediately life-threatening) | I11: Sweden | J11: Joint Nordic HTA (FINOSE/JNHB) | K11: FINOSE Joint Health Economic Assessment + NT-rådet recommendation | L11: Recommended | M11: Positive | N11: Broad | O11: N/A | P11: 2022 | Q11: FINOSE HTA February 2022; NT-rådet recommendation November 2023 | R11: Best supportive care / no active treatment | S11: BSC | T11: Not specified / unclear | U11: Clinical evidence uncertainty + Comparator/positioning issue | V11: Approx. NOK 3.15–3.23 million/QALY in FINOSE scenarios; combined scenario approx. NOK 6.36 million/QALY | W11: Very small patient population, no randomized comparator, uncertainty regarding long-term durability and safety | X11: Late infantile or early juvenile MLD; presymptomatic patients or early symptomatic patients still able to walk independently and before cognitive decline | Y11: Joint FINOSE assessment with Norway and Finland | Z11: Sweden became the operational treatment hub for the Nordic region | AA11: Primary xlsx database | AB11: 7 | AC11: =IF(OR($M11="Positive",$M11="Restricted Positive"),1,0) -> 1 | AD11: =IF($M11="Not Evaluated",0,1) -> 1 | AG11: source quotes NOK 3.15-6.36M in the Sweden record - likely a currency labelling error in source data, excluded pending verification | AH11: Gene therapy | AI11: =IF(COUNTIFS($A$2:$A$175,$A11,$C$2:$C$175,$C11,$AC$2:$AC$175,1)>0,1,0) -> 1 | AJ11: =IFERROR(_xludf.MINIFS($P$2:$P$175,$A$2:$A$175,$A11,$C$2:$C$175,$C11,$AC$2:$AC$175,1),"")
A12: Libmeldy | B12: Atidarsagene autotemcel | C12: Metachromatic leukodystrophy | D12: Orchard Therapeutics (Kyowa Kirin) | E12: Kyowa Kirin | F12: Gene therapy (ex vivo lentiviral) | G12: Neurology (metabolic) | H12: Ultra-severe (immediately life-threatening) | I12: Denmark | J12: Other / unclassified process | K12: Assessment initiated but not completed by Medicinrådet | L12: Outside Medicinrådet jurisdiction | M12: Not Evaluated | N12: Not Applicable | O12: Administrative/Procedural | P12: 2022 | Q12: 2022-06-01 00:00:00 | R12: Not applicable / Not assessed | S12: N/A | T12: Not specified / unclear | U12: Not specified | V12: N/A | W12: Danish patients referred through cross-border arrangements | X12: Not evaluated because treatment delivered abroad | Y12: Medicinrådet concluded that treatment falls outside its mandate because Danish patients are treated abroad | Z12: Access ultimately achieved through Nordic collaboration rather than standard Medicinrådet recommendation | AA12: Primary xlsx database | AB12: 7 | AC12: =IF(OR($M12="Positive",$M12="Restricted Positive"),1,0) -> 0 | AD12: =IF($M12="Not Evaluated",0,1) -> 0 | AH12: Gene therapy | AI12: =IF(COUNTIFS($A$2:$A$175,$A12,$C$2:$C$175,$C12,$AC$2:$AC$175,1)>0,1,0) -> 1 | AJ12: =IFERROR(_xludf.MINIFS($P$2:$P$175,$A$2:$A$175,$A12,$C$2:$C$175,$C12,$AC$2:$AC$175,1),"")
A13: Libmeldy | B13: Atidarsagene autotemcel | C13: Metachromatic leukodystrophy | D13: Orchard Therapeutics (Kyowa Kirin) | E13: Kyowa Kirin | F13: Gene therapy (ex vivo lentiviral) | G13: Neurology (metabolic) | H13: Ultra-severe (immediately life-threatening) | I13: Norway | J13: Joint Nordic HTA (FINOSE/JNHB) | K13: Rapid HTA (Cost-Utility Assessment) + FINOSE Collaboration | L13: Recommended | M13: Positive | N13: Broad | O13: N/A | P13: 2023 | Q13: 2023-06-19 00:00:00 | R13: Best supportive care / no active treatment | S13: BSC | T13: Not specified / unclear | U13: Clinical evidence uncertainty + Price / cost-effectiveness | V13: Based on FINOSE cost-effectiveness assessment; exact negotiated price confidential | W13: Long-term durability, small evidence base, no control group | X13: Same population as EMA indication; treatment centralized to Nordic centre in Sweden | Y13: Norwegian adaptation of FINOSE assessment plus national price negotiations | Z13: Explicitly linked to Nordic collaboration and newborn screening discussion | AA13: Primary xlsx database | AB13: 7 | AC13: =IF(OR($M13="Positive",$M13="Restricted Positive"),1,0) -> 1 | AD13: =IF($M13="Not Evaluated",0,1) -> 1 | AH13: Gene therapy | AI13: =IF(COUNTIFS($A$2:$A$175,$A13,$C$2:$C$175,$C13,$AC$2:$AC$175,1)>0,1,0) -> 1 | AJ13: =IFERROR(_xludf.MINIFS($P$2:$P$175,$A$2:$A$175,$A13,$C$2:$C$175,$C13,$AC$2:$AC$175,1),"")
A14: Skysona | B14: Elivaldogene autotemcel | C14: Cerebral adrenoleukodystrophy | D14: Bluebird Bio | E14: bluebird bio | F14: Gene therapy (ex vivo lentiviral) | G14: Neurology (metabolic) | H14: Ultra-severe (immediately life-threatening) | I14: Sweden | J14: Early / horizon scanning only | K14: Early Assessment Report (Horizon Scanning) | L14: Withdrawn before HTA completion | M14: Withdrawn | N14: Not Applicable | O14: Administrative/Procedural | P14: 2021 | Q14: Early Assessment 04/05/2021; European withdrawal November 2021 | R14: Procedural / transplant-based comparator | S14: Allogeneic Hematopoietic Stem Cell Transplantation (HSCT) | T14: Not specified / unclear | U14: Administrative/procedural + Clinical evidence uncertainty | V14: N/A | W14: Limited clinical evidence, immature long-term data, uncertainty regarding durability, safety, implementation and expected pricing | X14: Intended for boys <18 years with early cerebral adrenoleukodystrophy (cALD) and ABCD1 mutation | Y14: Early assessment only. No TLV economic assessment, reimbursement review or NT-rådet recommendation completed. | Z14: Important failed market access case. Despite EMA approval in July 2021, Bluebird Bio withdrew Skysona from Europe in November 2021 following broader reimbursement and pricing challenges. No Nordic reimbursement process was completed and the therapy never entered routine clinical practice. | AA14: Primary xlsx database | AB14: 8 | AC14: =IF(OR($M14="Positive",$M14="Restricted Positive"),1,0) -> 0 | AD14: =IF($M14="Not Evaluated",0,1) -> 1 | AG14: none public - withdrawn before HTA completion | AH14: Gene therapy | AI14: =IF(COUNTIFS($A$2:$A$175,$A14,$C$2:$C$175,$C14,$AC$2:$AC$175,1)>0,1,0) -> 0 | AJ14: =IFERROR(_xludf.MINIFS($P$2:$P$175,$A$2:$A$175,$A14,$C$2:$C$175,$C14,$AC$2:$AC$175,1),"")
A15: Skysona | B15: Elivaldogene autotemcel | C15: Cerebral adrenoleukodystrophy | D15: Bluebird Bio | E15: bluebird bio | F15: Gene therapy (ex vivo lentiviral) | G15: Neurology (metabolic) | H15: Ultra-severe (immediately life-threatening) | I15: Denmark | J15: No formal assessment / not assessed | K15: Not assessed in Denmark | L15: Not assessed in Denmark | M15: Not Evaluated | N15: Not Applicable | O15: N/A | Q15: Not assessed in Denmark | R15: Not applicable / Not assessed | S15: Not assessed in Denmark | T15: Not specified / unclear | U15: Not specified | V15: Not assessed in Denmark | W15: Not assessed in Denmark | X15: Not assessed in Denmark | Y15: Not assessed in Denmark | Z15: Not assessed in Denmark | AA15: Primary xlsx database | AB15: 8 | AC15: =IF(OR($M15="Positive",$M15="Restricted Positive"),1,0) -> 0 | AD15: =IF($M15="Not Evaluated",0,1) -> 0 | AH15: Gene therapy | AI15: =IF(COUNTIFS($A$2:$A$175,$A15,$C$2:$C$175,$C15,$AC$2:$AC$175,1)>0,1,0) -> 0 | AJ15: =IFERROR(_xludf.MINIFS($P$2:$P$175,$A$2:$A$175,$A15,$C$2:$C$175,$C15,$AC$2:$AC$175,1),"")
A16: Skysona | B16: Elivaldogene autotemcel | C16: Cerebral adrenoleukodystrophy | D16: Bluebird Bio | E16: bluebird bio | F16: Gene therapy (ex vivo lentiviral) | G16: Neurology (metabolic) | H16: Ultra-severe (immediately life-threatening) | I16: Norway | J16: No formal assessment / not assessed | K16: Not assessed in Norway | L16: Not assessed in Norway | M16: Not Evaluated | N16: Not Applicable | O16: N/A | Q16: Not assessed in Norway | R16: Not applicable / Not assessed | S16: Not assessed in Norway | T16: Not specified / unclear | U16: Not specified | V16: Not assessed in Norway | W16: Not assessed in Norway | X16: Not assessed in Norway | Y16: Not assessed in Norway | Z16: Not assessed in Norway | AA16: Primary xlsx database | AB16: 8 | AC16: =IF(OR($M16="Positive",$M16="Restricted Positive"),1,0) -> 0 | AD16: =IF($M16="Not Evaluated",0,1) -> 0 | AH16: Gene therapy | AI16: =IF(COUNTIFS($A$2:$A$175,$A16,$C$2:$C$175,$C16,$AC$2:$AC$175,1)>0,1,0) -> 0 | AJ16: =IFERROR(_xludf.MINIFS($P$2:$P$175,$A$2:$A$175,$A16,$C$2:$C$175,$C16,$AC$2:$AC$175,1),"")
A17: Hemgenix | B17: Etranacogene dezaparvovec | C17: Hemophilia B | D17: CSL Behring | E17: CSL Behring | F17: Gene therapy (in vivo AAV) | G17: Hematology | H17: Serious (chronic, manageable) | I17: Sweden | J17: Full / standard HTA | K17: Health Economic Assessment with Scenario Analysis + NT-rådet recommendation | L17: Not recommended | M17: Negative | N17: Not Applicable | O17: Price/Cost-effectiveness | P17: 2023 | Q17: TLV assessment 18/09/2023; NT-rådet final recommendation 25/04/2025 | R17: Other / mixed comparator | S17: Prophylactic FIX concentrates | T17: Not specified / unclear | U17: Clinical evidence uncertainty + Price / cost-effectiveness | V17: TLV scenario: Hemgenix can be dominant if effect is sustained over model horizon, but uncertainty remains high; NT-rådet concluded it was not cost-effective after failed price reduction negotiation | W17: High scientific uncertainty and very high health-economic uncertainty; durability of one-time gene therapy effect unknown; no direct comparative study versus FIX prophylaxis; effect advantage versus current well-functioning treatment unclear | X17: Adults with severe or moderately severe hemophilia B without history of FIX inhibitors | Y17: NT-rådet recommended regions not to use Hemgenix. Negotiation did not produce sufficient cost reduction, and even an outcome-based agreement was judged insufficient | Z17: Clear negative access case. Current Swedish FIX prophylaxis is considered well-functioning, reducing disease severity and making the acceptable price for gene therapy harder to justify. | AA17: Primary xlsx database | AB17: 9 | AC17: =IF(OR($M17="Positive",$M17="Restricted Positive"),1,0) -> 0 | AD17: =IF($M17="Not Evaluated",0,1) -> 1 | AG17: no ICER reported; TLV scenario-dependent (dominant-to-uncertain) | AH17: Gene therapy | AI17: =IF(COUNTIFS($A$2:$A$175,$A17,$C$2:$C$175,$C17,$AC$2:$AC$175,1)>0,1,0) -> 1 | AJ17: =IFERROR(_xludf.MINIFS($P$2:$P$175,$A$2:$A$175,$A17,$C$2:$C$175,$C17,$AC$2:$AC$175,1),"")
A18: Hemgenix | B18: Etranacogene dezaparvovec | C18: Hemophilia B | D18: CSL Behring | E18: CSL Behring | F18: Gene therapy (in vivo AAV) | G18: Hematology | H18: Serious (chronic, manageable) | I18: Denmark | J18: Managed introduction / price negotiation | K18: Medicinrådet recommendation + reassessment + Amgros alternative price agreement | L18: 2023: Not recommended. 2024: Recommended | M18: Positive | N18: Broad | O18: N/A | P18: 2023 | Q18: Not recommended 22/11/2023; recommended 19/06/2024 | R18: Active comparator drug(s) | S18: FIX prophylaxis, especially Refixia | T18: Not specified / unclear | U18: Clinical evidence uncertainty + Price / cost-effectiveness | V18: No public ICER. 2023 analysis found Hemgenix could be dominant at AIP/SAIP but this was highly uncertain and dependent on long response duration. 2024 recommendation accepted costs as reasonable after alternative price agreement | W18: Long-term durability, sparse long-term safety data, uncertainty about how many patients will need to restart FIX prophylaxis | X18: Adults with severe or moderately severe hemophilia B without history of FIX inhibitors | Y18: Initial rejection due to price and uncertainty; later recommendation after new agreement where payment is linked to continued effect | Z18: Denmark is the positive contrast to Sweden: same core uncertainty, but access achieved through risk-sharing/payment-linked agreement. | AA18: Primary xlsx database | AB18: 9 | AC18: =IF(OR($M18="Positive",$M18="Restricted Positive"),1,0) -> 1 | AD18: =IF($M18="Not Evaluated",0,1) -> 1 | AH18: Gene therapy | AI18: =IF(COUNTIFS($A$2:$A$175,$A18,$C$2:$C$175,$C18,$AC$2:$AC$175,1)>0,1,0) -> 1 | AJ18: =IFERROR(_xludf.MINIFS($P$2:$P$175,$A$2:$A$175,$A18,$C$2:$C$175,$C18,$AC$2:$AC$175,1),"")
A19: Hemgenix | B19: Etranacogene dezaparvovec | C19: Hemophilia B | D19: CSL Behring | E19: CSL Behring | F19: Gene therapy (in vivo AAV) | G19: Hematology | H19: Serious (chronic, manageable) | I19: Norway | J19: Managed introduction / price negotiation | K19: Full Method Assessment (Metodevurdering) + Price Note | L19: Recommended / Introduced | M19: Positive | N19: Broad | O19: N/A | P19: 2026 | Q19: 2026-03-16 00:00:00 | R19: Active comparator drug(s) | S19: Standard FIX prophylaxis (factor IX replacement therapy) | T19: Not specified / unclear | U19: Clinical evidence uncertainty + Price / cost-effectiveness | V19: Full cost-effectiveness analysis conducted; ICER not publicly available due to confidential pricing | W19: Long-term durability of FIX expression; uncertainty regarding duration of treatment effect; extrapolation beyond trial follow-up | X19: Price must be equal to or lower than negotiated price; treatment centralized at Oslo University Hospital | Y19: DMP performed full HTA assessing severity, benefit, resource use, uncertainty and budget impact. Final approval followed price negotiations by Sykehusinnkjøp. | Z19: Major contrast with Sweden. Norway ultimately approved gene therapy after centralized negotiations and national funding. | AA19: Primary xlsx database | AB19: 9 | AC19: =IF(OR($M19="Positive",$M19="Restricted Positive"),1,0) -> 1 | AD19: =IF($M19="Not Evaluated",0,1) -> 1 | AH19: Gene therapy | AI19: =IF(COUNTIFS($A$2:$A$175,$A19,$C$2:$C$175,$C19,$AC$2:$AC$175,1)>0,1,0) -> 1 | AJ19: =IFERROR(_xludf.MINIFS($P$2:$P$175,$A$2:$A$175,$A19,$C$2:$C$175,$C19,$AC$2:$AC$175,1),"")
A20: Roctavian | B20: Valoctocogene roxaparvovec | C20: Hemophilia A | D20: BioMarin International Limited | E20: BioMarin | F20: Gene therapy (in vivo AAV) | G20: Hematology | H20: Serious (chronic, manageable) | I20: Sweden | J20: Full / standard HTA | K20: Health Economic Assessment with Scenario Analysis + NT-rådet wait recommendation | L20: Not recommended / wait; not marketed in Sweden | M20: Negative | N20: Not Applicable | O20: Administrative/Procedural | P20: 2024 | Q20: TLV assessment 29/08/2024; NT-rådet wait recommendation 19/12/2024 | R20: Active comparator drug(s) | S20: Prophylactic FVIII concentrates; Hemlibra considered in model | T20: Not specified / unclear | U20: Clinical evidence uncertainty | V20: TLV base scenario: Roctavian dominant versus FVIII prophylaxis, meaning more effective and lower cost, but only under uncertain assumptions about duration of effect and long-term cost offsets | W20: Very high uncertainty around durability of gene therapy effect, declining FVIII activity over time, representativeness of GENEr8-1 patients for Swedish well-controlled patients, HRQoL assumptions and lack of long-term data | X20: Adults with severe hemophilia A without history of FVIII inhibitors and without detectable AAV5 antibodies | Y20: TLV completed the health economic assessment, but NT-rådet could not proceed to final recommendation/contracting because BioMarin stated Roctavian would not be marketed in Sweden | Z20: Important “non-launch after HTA” case. Unlike Skysona, Sweden completed the HTA, but market access stopped because the company did not commercialize the medicine in Sweden. | AA20: Primary xlsx database | AB20: 10 | AC20: =IF(OR($M20="Positive",$M20="Restricted Positive"),1,0) -> 0 | AD20: =IF($M20="Not Evaluated",0,1) -> 1 | AG20: no ICER reported; TLV scenario-dependent (dominant under uncertain assumptions) | AH20: Gene therapy | AI20: =IF(COUNTIFS($A$2:$A$175,$A20,$C$2:$C$175,$C20,$AC$2:$AC$175,1)>0,1,0) -> 0 | AJ20: =IFERROR(_xludf.MINIFS($P$2:$P$175,$A$2:$A$175,$A20,$C$2:$C$175,$C20,$AC$2:$AC$175,1),"")
A21: Roctavian | B21: Valoctocogene roxaparvovec | C21: Hemophilia A | D21: BioMarin International Limited | E21: BioMarin | F21: Gene therapy (in vivo AAV) | G21: Hematology | H21: Serious (chronic, manageable) | I21: Denmark | J21: No formal assessment / not assessed | K21: Not assessed in Denmark | L21: Not assessed in Denmark | M21: Not Evaluated | N21: Not Applicable | O21: N/A | Q21: Not assessed in Denmark | R21: Not applicable / Not assessed | S21: Not assessed in Denmark | T21: Not specified / unclear | U21: Not specified | V21: Not assessed in Denmark | W21: Not assessed in Denmark | X21: Not assessed in Denmark | Y21: Not assessed in Denmark | Z21: Not assessed in Denmark | AA21: Primary xlsx database | AB21: 10 | AC21: =IF(OR($M21="Positive",$M21="Restricted Positive"),1,0) -> 0 | AD21: =IF($M21="Not Evaluated",0,1) -> 0 | AH21: Gene therapy | AI21: =IF(COUNTIFS($A$2:$A$175,$A21,$C$2:$C$175,$C21,$AC$2:$AC$175,1)>0,1,0) -> 0 | AJ21: =IFERROR(_xludf.MINIFS($P$2:$P$175,$A$2:$A$175,$A21,$C$2:$C$175,$C21,$AC$2:$AC$175,1),"")
A22: Roctavian | B22: Valoctocogene roxaparvovec | C22: Hemophilia A | D22: BioMarin International Limited | E22: BioMarin | F22: Gene therapy (in vivo AAV) | G22: Hematology | H22: Serious (chronic, manageable) | I22: Norway | J22: Rapid / simplified HTA | K22: Rapid HTA (Hurtig metodevurdering) + Cost-Utility Assessment | L22: Not launched / Withdrawn | M22: Withdrawn | N22: Not Applicable | O22: Administrative/Procedural | P22: 2025 | Q22: 2025-01-20 00:00:00 | R22: Active comparator drug(s) | S22: Standard FVIII prophylaxis | T22: Not specified / unclear | U22: Administrative/procedural + Clinical evidence uncertainty | V22: Evaluated but no reimbursement decision reached | W22: Durability of gene expression; long-term effectiveness; uncertainty around duration of benefit | Y22: Full assessment completed by DMP but manufacturer decided not to launch in Norway and subsequently withdrew product from market. | Z22: Similar outcome to Sweden, but due to manufacturer withdrawal rather than formal reimbursement rejection. | AA22: Primary xlsx database | AB22: 10 | AC22: =IF(OR($M22="Positive",$M22="Restricted Positive"),1,0) -> 0 | AD22: =IF($M22="Not Evaluated",0,1) -> 1 | AH22: Gene therapy | AI22: =IF(COUNTIFS($A$2:$A$175,$A22,$C$2:$C$175,$C22,$AC$2:$AC$175,1)>0,1,0) -> 0 | AJ22: =IFERROR(_xludf.MINIFS($P$2:$P$175,$A$2:$A$175,$A22,$C$2:$C$175,$C22,$AC$2:$AC$175,1),"")
A23: Hemlibra | B23: emicizumab | C23: Hemophilia A | D23: Roche AB | E23: Roche | F23: Monoclonal antibody (bispecific) | G23: Hematology | H23: Serious (chronic, manageable) | I23: Sweden | J23: Managed introduction / price negotiation | K23: Reimbursement/Subvention Assessment with Cost-Minimisation Analysis + side agreement | L23: Reimbursed / general subvention | M23: Positive | N23: Broad | O23: N/A | P23: 2022 | Q23: 2022-06-01 00:00:00 | R23: Best supportive care / no active treatment | S23: TLV used no treatment as formal comparator due to confidential FVIII net prices; FVIII prophylaxis clinically relevant | T23: Not specified / unclear | U23: Clinical evidence uncertainty + Price / cost-effectiveness | V23: No ICER reported; TLV used cost-minimisation and judged Hemlibra costs reasonable after side agreement | W23: Uncertainty from indirect comparisons, differences between study populations, lack of public net prices for FVIII concentrates, long-term treatment assumptions | X23: Hemophilia A with FVIII inhibitors and severe hemophilia A without inhibitors; all age groups within approved indication | Y23: Hemlibra had restricted reimbursement since 2018 and received broader/general reimbursement in 2022 after three-party negotiations and a side agreement | Z23: Essential market context for hemophilia A. Subcutaneous prophylaxis changed the treatment landscape and is relevant when assessing Roctavian’s incremental value. | AA23: Primary xlsx database | AB23: 11 | AC23: =IF(OR($M23="Positive",$M23="Restricted Positive"),1,0) -> 1 | AD23: =IF($M23="Not Evaluated",0,1) -> 1 | AG23: none public - cost-minimisation approach, not cost-utility | AH23: Monoclonal antibody | AI23: =IF(COUNTIFS($A$2:$A$175,$A23,$C$2:$C$175,$C23,$AC$2:$AC$175,1)>0,1,0) -> 1 | AJ23: =IFERROR(_xludf.MINIFS($P$2:$P$175,$A$2:$A$175,$A23,$C$2:$C$175,$C23,$AC$2:$AC$175,1),"")
A24: Hemlibra | B24: emicizumab | C24: Hemophilia A | D24: Roche AB | E24: Roche | F24: Monoclonal antibody (bispecific) | G24: Hematology | H24: Serious (chronic, manageable) | I24: Denmark | J24: Other / unclassified process | K24: Included in Medicinrådet hemophilia A treatment guideline and drug recommendation | L24: Recommended / established standard-of-care option | M24: Positive | N24: Broad | O24: N/A | P24: 2026 | Q24: Current hemophilia A recommendation effective 01/05/2026 | R24: Active comparator drug(s) | S24: FVIII prophylaxis and newer alternatives such as Altuvoct and marstacimab | T24: Not specified / unclear | U24: Comparator/positioning issue + Price / cost-effectiveness | V24: No ICER in current recommendation; ranked through treatment guideline and cost-based recommendation logic | W24: Treatment positioning, cost ranking, patient selection versus FVIII products | X24: Hemophilia A, especially patients where FVIII prophylaxis is unsuitable, insufficient or difficult to administer | Y24: Used as key comparator/context in later Danish hemophilia A evaluations | Z24: Essential context row. Hemlibra explains why hemophilia A gene therapies must prove value against a strong, convenient subcutaneous standard. | AA24: Primary xlsx database | AB24: 11 | AC24: =IF(OR($M24="Positive",$M24="Restricted Positive"),1,0) -> 1 | AD24: =IF($M24="Not Evaluated",0,1) -> 1 | AH24: Monoclonal antibody | AI24: =IF(COUNTIFS($A$2:$A$175,$A24,$C$2:$C$175,$C24,$AC$2:$AC$175,1)>0,1,0) -> 1 | AJ24: =IFERROR(_xludf.MINIFS($P$2:$P$175,$A$2:$A$175,$A24,$C$2:$C$175,$C24,$AC$2:$AC$175,1),"")
A25: Hemlibra | B25: emicizumab | C25: Hemophilia A | D25: Roche AB | E25: Roche | F25: Monoclonal antibody (bispecific) | G25: Hematology | H25: Serious (chronic, manageable) | I25: Norway | J25: Rapid / simplified HTA | K25: Rapid HTA (Hurtig metodevurdering) | L25: Recommended | M25: Positive | N25: Broad | O25: N/A | P25: 2018 | Q25: 2018-12-17 00:00:00 | R25: Active comparator drug(s) | S25: Bypassing agents and existing prophylaxis for inhibitor patients | T25: Not specified / unclear | U25: Not specified | V25: Cost-effectiveness assessment conducted; exact ICER confidential | W25: Limited long-term evidence and indirect comparisons | X25: Price equal to or below negotiated level | Y25: Approved for Hemophilia A patients with inhibitors after HTA review. | Z25: Became standard prophylaxis option for inhibitor population. | AA25: Primary xlsx database | AB25: 11 | AC25: =IF(OR($M25="Positive",$M25="Restricted Positive"),1,0) -> 1 | AD25: =IF($M25="Not Evaluated",0,1) -> 1 | AH25: Monoclonal antibody | AI25: =IF(COUNTIFS($A$2:$A$175,$A25,$C$2:$C$175,$C25,$AC$2:$AC$175,1)>0,1,0) -> 1 | AJ25: =IFERROR(_xludf.MINIFS($P$2:$P$175,$A$2:$A$175,$A25,$C$2:$C$175,$C25,$AC$2:$AC$175,1),"")
A26: Beqvez | B26: Fidanacogene elaparvovec | C26: Hemophilia B | D26: Pfizer | E26: Pfizer | F26: Gene therapy (in vivo AAV) | G26: Hematology | H26: Serious (chronic, manageable) | I26: Sweden | J26: No formal assessment / not assessed | K26: Not assessed in sweden - withdrawn drom European Commercialization | L26: Not assessed in sweden - withdrawn drom European Commercialization | M26: Withdrawn | N26: Not Applicable | O26: Administrative/Procedural | Q26: Not assessed in sweden - withdrawn drom European Commercialization | R26: Not applicable / Not assessed | S26: Not assessed in sweden - withdrawn drom European Commercialization | T26: Not specified / unclear | U26: Administrative/procedural | V26: Not assessed in sweden - withdrawn drom European Commercialization | W26: Not assessed in sweden - withdrawn drom European Commercialization | X26: Not assessed in sweden - withdrawn drom European Commercialization | Y26: Not assessed in sweden - withdrawn drom European Commercialization | Z26: Not assessed in sweden - withdrawn drom European Commercialization | AA26: Primary xlsx database | AB26: 12 | AC26: =IF(OR($M26="Positive",$M26="Restricted Positive"),1,0) -> 0 | AD26: =IF($M26="Not Evaluated",0,1) -> 1 | AG26: not assessed in Sweden | AH26: Gene therapy | AI26: =IF(COUNTIFS($A$2:$A$175,$A26,$C$2:$C$175,$C26,$AC$2:$AC$175,1)>0,1,0) -> 0 | AJ26: =IFERROR(_xludf.MINIFS($P$2:$P$175,$A$2:$A$175,$A26,$C$2:$C$175,$C26,$AC$2:$AC$175,1),"")
A27: Beqvez | B27: Fidanacogene elaparvovec | C27: Hemophilia B | D27: Pfizer | E27: Pfizer | F27: Gene therapy (in vivo AAV) | G27: Hematology | H27: Serious (chronic, manageable) | I27: Denmark | J27: Full / standard HTA | K27: Medicinrådet assessment initiated but discontinued | L27: Withdrawn | M27: Withdrawn | N27: Not Applicable | O27: Administrative/Procedural | P27: 2023 | Q27: Request received 12/11/2023; withdrawn 28/05/2024 | R27: Active comparator drug(s) | S27: Expected comparator: FIX prophylaxis | T27: Not specified / unclear | U27: Administrative/procedural + Clinical evidence uncertainty + Price / cost-effectiveness | V27: N/A | W27: Not assessed; expected uncertainty around durability, safety, comparative benefit and price | X27: Hemophilia B gene therapy population | Y27: Application withdrawn before recommendation | Z27: Important watchlist/failure-to-complete case. Denmark has access to Hemgenix, while Beqvez did not complete the Danish process. | AA27: Primary xlsx database | AB27: 12 | AC27: =IF(OR($M27="Positive",$M27="Restricted Positive"),1,0) -> 0 | AD27: =IF($M27="Not Evaluated",0,1) -> 1 | AH27: Gene therapy | AI27: =IF(COUNTIFS($A$2:$A$175,$A27,$C$2:$C$175,$C27,$AC$2:$AC$175,1)>0,1,0) -> 0 | AJ27: =IFERROR(_xludf.MINIFS($P$2:$P$175,$A$2:$A$175,$A27,$C$2:$C$175,$C27,$AC$2:$AC$175,1),"")
A28: Beqvez | B28: Fidanacogene elaparvovec | C28: Hemophilia B | D28: Pfizer | E28: Pfizer | F28: Gene therapy (in vivo AAV) | G28: Hematology | H28: Serious (chronic, manageable) | I28: Norway | J28: Other / unclassified process | K28: Withrawn from EMA | L28: Withrawn from EMA | M28: Withdrawn | N28: Not Applicable | O28: Administrative/Procedural | Q28: Withrawn from EMA | R28: Other / mixed comparator | S28: Withrawn from EMA | T28: Not specified / unclear | U28: Not specified | V28: Withrawn from EMA | W28: Withrawn from EMA | X28: Withrawn from EMA | Y28: Withrawn from EMA | Z28: Withrawn from EMA | AA28: Primary xlsx database | AB28: 12 | AC28: =IF(OR($M28="Positive",$M28="Restricted Positive"),1,0) -> 0 | AD28: =IF($M28="Not Evaluated",0,1) -> 1 | AH28: Gene therapy | AI28: =IF(COUNTIFS($A$2:$A$175,$A28,$C$2:$C$175,$C28,$AC$2:$AC$175,1)>0,1,0) -> 0 | AJ28: =IFERROR(_xludf.MINIFS($P$2:$P$175,$A$2:$A$175,$A28,$C$2:$C$175,$C28,$AC$2:$AC$175,1),"")
A29: Hympavzi | B29: marstacimab | C29: Hemophilia A and B | D29: Pfizer | E29: Pfizer | F29: Monoclonal antibody | G29: Hematology | H29: Serious (chronic, manageable) | I29: Sweden | J29: Early / horizon scanning only | K29: Early assessment / monitoring (no completed TLV reimbursement decision identified) | L29: No Swedish reimbursement decision identified / under market access monitoring | M29: Ongoing/Pending | N29: Not Applicable | O29: N/A | Q29: N/A | R29: Active comparator drug(s) | S29: Hemlibra, Alhemo, FVIII/FIX prophylaxis (expected comparators) | T29: Not specified / unclear | U29: Comparator/positioning issue | V29: N/A | W29: Pricing and positioning versus established non-factor prophylaxis therapies; limited Swedish HTA information currently available | X29: N/A | Y29: No completed Swedish HTA or reimbursement assessment identified at present. Appears mainly in pipeline and early assessment discussions. | Z29: Important emerging competitor. In Denmark it was directly incorporated into national treatment guidelines, highlighting different Nordic access approaches. | AA29: Primary xlsx database | AB29: 13 | AC29: =IF(OR($M29="Positive",$M29="Restricted Positive"),1,0) -> 0 | AD29: =IF($M29="Not Evaluated",0,1) -> 1 | AG29: ongoing/pending | AH29: Monoclonal antibody | AI29: =IF(COUNTIFS($A$2:$A$175,$A29,$C$2:$C$175,$C29,$AC$2:$AC$175,1)>0,1,0) -> 1 | AJ29: =IFERROR(_xludf.MINIFS($P$2:$P$175,$A$2:$A$175,$A29,$C$2:$C$175,$C29,$AC$2:$AC$175,1),"")
A30: Hympavzi | B30: marstacimab | C30: Hemophilia A and B | D30: Pfizer | E30: Pfizer | F30: Monoclonal antibody | G30: Hematology | H30: Serious (chronic, manageable) | I30: Denmark | J30: Other / unclassified process | K30: Direct placement into Medicinrådet hemophilia A and B treatment guidelines | L30: Recommended / placed in guideline | M30: Positive | N30: Broad | O30: N/A | P30: 2025 | Q30: Direct placement approved 03/09/2025; recommendation effective 01/05/2026 | R30: Active comparator drug(s) | S30: Hemlibra for hemophilia A; relevant hemophilia B prophylaxis alternatives | T30: Not specified / unclear | U30: Comparator/positioning issue | V30: No ICER; direct placement based on evidence review and Amgros negotiation | W30: Comparative evidence and positioning versus existing prophylaxis options | X30: Patients ≥12 years and ≥35 kg with severe hemophilia A or B without inhibitors | Y30: Added to both hemophilia A and B pathways | Z30: Not gene therapy, but important because it shows Denmark is actively expanding non-factor prophylaxis options. | AA30: Primary xlsx database | AB30: 13 | AC30: =IF(OR($M30="Positive",$M30="Restricted Positive"),1,0) -> 1 | AD30: =IF($M30="Not Evaluated",0,1) -> 1 | AH30: Monoclonal antibody | AI30: =IF(COUNTIFS($A$2:$A$175,$A30,$C$2:$C$175,$C30,$AC$2:$AC$175,1)>0,1,0) -> 1 | AJ30: =IFERROR(_xludf.MINIFS($P$2:$P$175,$A$2:$A$175,$A30,$C$2:$C$175,$C30,$AC$2:$AC$175,1),"")
A31: Hympavzi | B31: marstacimab | C31: Hemophilia A and B | D31: Pfizer | E31: Pfizer | F31: Monoclonal antibody | G31: Hematology | H31: Serious (chronic, manageable) | I31: Norway | J31: Full / standard HTA | K31: Single-drug Method Assessment (without full economic model) | L31: Under assessment / No final introduction decision identified | M31: Ongoing/Pending | N31: Not Applicable | O31: N/A | P31: 2026 | Q31: 03/02/2026 (assessment publication) | R31: Active comparator drug(s) | S31: Personalized FVIII/FIX prophylaxis; existing standard prophylaxis | T31: Not specified / unclear | U31: Not specified | V31: No ICER reported | W31: Clinical benefit versus optimized prophylaxis; higher annualized joint bleeding rates than existing individualized treatment strategies | X31: None yet | Y31: DMP completed clinical assessment for severe Hemophilia A and B without inhibitors. | Z31: Norway appears more cautious than Sweden regarding newer non-factor prophylaxis agents when effective standard factor treatment already exists. | AA31: Primary xlsx database | AB31: 13 | AC31: =IF(OR($M31="Positive",$M31="Restricted Positive"),1,0) -> 0 | AD31: =IF($M31="Not Evaluated",0,1) -> 1 | AH31: Monoclonal antibody | AI31: =IF(COUNTIFS($A$2:$A$175,$A31,$C$2:$C$175,$C31,$AC$2:$AC$175,1)>0,1,0) -> 1 | AJ31: =IFERROR(_xludf.MINIFS($P$2:$P$175,$A$2:$A$175,$A31,$C$2:$C$175,$C31,$AC$2:$AC$175,1),"")
A32: Alhemo | B32: concizumab | C32: Hemophilia B | D32: Novo Nordisk AB | E32: Novo Nordisk | F32: Monoclonal antibody | G32: Hematology | H32: Serious (chronic, manageable) | I32: Sweden | J32: Full / standard HTA | K32: Reimbursement/Subvention Assessment + Cost Comparison | L32: Reimbursed with restriction | M32: Restricted Positive | N32: Restricted | O32: N/A | P32: 2025 | Q32: 21/11/2025 (effective 25/11/2025) | R32: Active comparator drug(s) | S32: NovoSeven (eptacog alfa activated) | T32: Not specified / unclear | U32: Price / cost-effectiveness | V32: No ICER reported; cost-comparison approach. Lower treatment cost than NovoSeven | W32: No direct comparative trials; reliance on indirect comparison; differences between study populations and study designs | X32: Only reimbursed for Hemophilia B patients with inhibitors where immune tolerance induction (ITI) failed | Y32: TLV concluded Alhemo provides at least comparable efficacy with lower drug costs than NovoSeven, resulting in reimbursement for a narrow inhibitor population. | Z32: Good example of successful market access by targeting a small, high-cost niche population where economic value is easier to demonstrate. | AA32: Primary xlsx database | AB32: 14 | AC32: =IF(OR($M32="Positive",$M32="Restricted Positive"),1,0) -> 1 | AD32: =IF($M32="Not Evaluated",0,1) -> 1 | AG32: none public - cost-comparison approach, not cost-utility | AH32: Monoclonal antibody | AI32: =IF(COUNTIFS($A$2:$A$175,$A32,$C$2:$C$175,$C32,$AC$2:$AC$175,1)>0,1,0) -> 1 | AJ32: =IFERROR(_xludf.MINIFS($P$2:$P$175,$A$2:$A$175,$A32,$C$2:$C$175,$C32,$AC$2:$AC$175,1),"")
